<?xml version="1.0" ?>
<!-- =================================================================================== -->
<!-- |    This document was autogenerated by xacro from s650.xacro                     | -->
<!-- |    EDITING THIS FILE BY HAND IS NOT RECOMMENDED                                 | -->
<!-- =================================================================================== -->
<robot name="adept_s650" xmlns:xacro="http://ros.org/wiki/xacro">

  <material name="adept_light_grey">
    <color rgba="0.5 0.5 0.5 1"/>
  </material>
  <material name="adept_dark_grey">
    <color rgba="0.75 0.75 0.75 1"/>
  </material>
  <material name="blue">
    <color rgba="0 0 1 1"/>
  </material>

  <!-- link list -->
  <link name="base_link">
    <visual>
      <geometry>
        <cylinder length="0.203" radius="0.3"/>
      </geometry>
      <material name="adept_dark_grey">
      </material>
    </visual>
    <collision>
      <geometry>
        <cylinder length="0.203" radius="0.3"/>
      </geometry>
      <material name="blue"/>
    </collision>
  </link>
  <link name="link_1">
    <visual>
      <geometry>
        <cylinder length="0.132" radius="0.25"/>
      </geometry>
      <material name="adept_light_grey">
      </material>
    </visual>
    <collision>
      <geometry>
        <cylinder length="0.132" radius="0.25"/>
      </geometry>
      <material name="blue"/>
    </collision>
  </link>
  <link name="link_2">
    <visual>
      <geometry>
        <cylinder length="0.270" radius="0.25"/>
      </geometry>
      <material name="adept_dark_grey">
      </material>
    </visual>
    <collision>
      <geometry>
        <cylinder length="0.270" radius="0.25"/>
      </geometry>
      <material name="blue"/>
    </collision>
  </link>
  <link name="link_3">
    <visual>
      <geometry>
        <cylinder length="0.223" radius="0.2"/>
      </geometry>
      <material name="adept_light_grey">
      </material>
    </visual>
    <collision>
      <geometry>
        <cylinder length="0.223" radius="0.2"/>
      </geometry>
      <material name="blue"/>
    </collision>
  </link>
  <link name="link_4">
    <visual>
      <geometry>
        <cylinder length="0.192" radius="0.2"/>
      </geometry>
      <material name="adept_dark_grey">
      </material>
    </visual>
    <collision>
      <geometry>
        <cylinder length="0.192" radius="0.2"/>
      </geometry>
      <material name="blue"/>
    </collision>
  </link>
  <link name="link_5">
    <visual>
      <geometry>
        <cylinder length="0.08" radius="0.15"/>
      </geometry>
      <material name="adept_light_grey">
      </material>
    </visual>
    <collision>
      <geometry>
        <cylinder length="0.08" radius="0.15"/>
      </geometry>
      <material name="blue"/>
    </collision>
  </link>
  <link name="link_6">
    <visual>
      <geometry>
        <cylinder length="0.01" radius="0.15"/>
      </geometry>
      <material name="adept_dark_grey">
      </material>
    </visual>
    <collision>
      <geometry>
        <cylinder length="0.01" radius="0.15"/>
      </geometry>
      <material name="blue"/>
    </collision>
  </link>
  <!-- end of link list -->

  <!-- joint list -->
  <joint name="joint_1" type="revolute">
    <origin xyz="0 0 0.203" rpy="0 0 0"/>
    <parent link="base_link"/>
    <child link="link_1"/>
    <axis xyz="0 0 1"/>
    <limit effort="100" lower="-2.9670" upper="2.9670" velocity="5.72468"/>
  </joint>
  <joint name="joint_2" type="revolute">
    <origin xyz="0.074 0 0.18795" rpy="0 0 0"/>
    <parent link="link_1"/>
    <child link="link_2"/>
    <axis xyz="0 1 0"/>
    <limit effort="100" lower="-3.31613" upper="0.7854" velocity="5.235"/>
  </joint>
  <joint name="joint_3" type="revolute">
    <origin xyz="0.270 0 0" rpy="0 0 0"/>
    <parent link="link_2"/>
    <child link="link_3"/>
    <axis xyz="0 1 0"/>
    <limit effort="100" lower="-0.50615" upper="4.468053" velocity="6.544"/>
  </joint>
  <joint name="joint_4" type="revolute">
    <origin xyz="-0.090 0 0.295" rpy="0 0 0"/>
    <parent link="link_3"/>
    <child link="link_4"/>
    <axis xyz="0 0 1"/>
    <limit effort="100" lower="-3.31613" upper="3.316133" velocity="6.544"/>
  </joint>
  <joint name="joint_5" type="revolute">
    <origin xyz="0 0 0" rpy="0 0 0"/>
    <parent link="link_4"/>
    <child link="link_5"/>
    <axis xyz="0 1 0"/>
    <limit effort="100" lower="-2.0944" upper="2.0944" velocity="6.544"/>
  </joint>
  <joint name="joint_6" type="revolute">
    <origin xyz="0.0 0 0.08" rpy="0 0 0"/>
    <parent link="link_5"/>
    <child link="link_6"/>
    <axis xyz="0 0 1"/>
    <limit effort="100" lower="-3.1416" upper="3.1416" velocity="10.47"/>
  </joint>

  <!-- end of joint list -->
  <!-- ROS base_link to Adept World Coordinates transform - if necessary -->

</robot>
