<?xml version="1.0"?>
<robot xmlns:xacro="http://wiki.ros.org/xacro">
<xacro:macro name="arm">

    <!-- ################################################################# -->
    <!-- Kuka_LWR arm -->
    <!-- ################################################################# -->

    <material name="IPA/Orange">
      <color rgba="1.0 0.5 0.0 1.0"/>
    </material>
    <material name="black">
      <color rgba="0.5 0.5 0.5 1"/>
    </material>

    <link name="${name}_link_footprint"/>

    <link name="${name}_link_base">
    <visual>
      <origin xyz="0 0 0" rpy="0 0 0"/>
      <geometry>
        <box size="0.01 0.01 0.01"/>
      </geometry>
      <material name="black">
      </material>
    </visual>
    </link>

    <link name="${name}_link_1">
    <visual>
      <origin xyz="0 0 0" rpy="0 0 0" />
      <geometry>
        <mesh filename="package://klwr_description/mesh/joint_1.stl" />
      </geometry>
      <material name="IPA/Orange">
      </material>
    </visual>
    </link>

    <link name="${name}_link_2">
    <visual>
      <origin xyz="0 0 0" rpy="0 0 0" />
      <geometry>
        <mesh filename="package://klwr_description/mesh/joint_2.stl" />
      </geometry>
      <material name="IPA/Orange">
      </material>
    </visual>
    </link>

    <link name="${name}_link_3">
    <visual>
      <origin xyz="0 0 0" rpy="0 0 0" />
      <geometry>
        <mesh filename="package://klwr_description/mesh/joint_3.stl" />
      </geometry>
      <material name="IPA/Orange">
      </material>
    </visual>
    </link>

    <link name="${name}_link_4">
    <visual>
      <origin xyz="0 0 0" rpy="0 0 0" />
      <geometry>
        <mesh filename="package://klwr_description/mesh/joint_4.stl" />
      </geometry>
      <material name="IPA/Orange">
      </material>
    </visual>
    </link>

    <link name="${name}_link_5">
    <visual>
      <origin xyz="0 0 0" rpy="0 0 0" />
      <geometry>
        <mesh filename="package://klwr_description/mesh/joint_5.stl" />
      </geometry>
      <material name="IPA/Orange">
      </material>
    </visual>
    </link>

    <link name="${name}_link_6">
    <visual>
      <origin xyz="0 0 0" rpy="0 0 0" />
      <geometry>
        <mesh filename="package://klwr_description/mesh/joint_6.stl" />
      </geometry>
      <material name="IPA/Orange">
      </material>
    </visual>
    </link>

    <link name="${name}_link_7">
    <visual>
      <origin xyz="0 0 0" rpy="0 0 0" />
      <geometry>
        <mesh filename="package://klwr_description/mesh/joint_7.stl" />
      </geometry>
      <material name="IPA/Orange">
      </material>
    </visual>
    </link>

    <link name="${name}_link_tcp" />

    <joint name="${name}_joint_footprint" type="fixed" >
        <origin xyz="0 0 0.1185" rpy="0 0 0"/>
        <parent link="${name}_link_footprint" />
        <child link="${name}_link_base" />
    </joint>

    <joint name="${name}_joint_1" type="revolute">
        <origin xyz="0 0 0" rpy="0 0 0"/>
        <axis xyz="0 0 1"/>
        <limit effort="200" velocity="1.9634" lower="-2.9670" upper="2.9670"/>
        <parent link="${name}_link_base"/>
        <child link="${name}_link_1"/>
    </joint>

    <joint name="${name}_joint_2" type="revolute">
        <origin xyz="0 -0.002 0.1915" rpy="1.570796326 0 0"/>
        <axis xyz="0 0 1"/>
        <limit effort="200" velocity="1.9634" lower="-0.5235" upper="3.66509"/>
        <parent link="${name}_link_1"/>
        <child link="${name}_link_2"/>
    </joint>

    <joint name="${name}_joint_3" type="revolute">
        <origin xyz="0 0.2085 0" rpy="-1.570796326 0 0"/>
        <axis xyz="0 0 1"/>
        <limit effort="100" velocity="1.9634" lower="-2.9670" upper="2.9670"/>
        <parent link="${name}_link_2"/>
        <child link="${name}_link_3"/>
    </joint>

    <joint name="${name}_joint_4" type="revolute">
        <origin xyz="0 0.002 0.1915" rpy="-1.570796326 0 0" />
        <axis xyz="0 0 1" />
        <limit effort="100" velocity="1.9634" lower="-2.0943" upper="2.0943"/>
        <parent link="${name}_link_3"/>
        <child link="${name}_link_4"/>
    </joint>

    <joint name="${name}_joint_5" type="revolute">
        <origin xyz="0 -0.2085 0" rpy="1.570796326 0 0" />
        <axis xyz="0 0 1" />
        <limit effort="100" velocity="1.9634" lower="-2.9670" upper="2.9670" />
        <parent link="${name}_link_4"/>
        <child link="${name}_link_5"/>
    </joint>

    <joint name="${name}_joint_6" type="revolute">
        <origin xyz="0 0.046 0.1815" rpy="1.570796326 0 0" />
        <axis xyz="0 0 1" />
        <limit effort="30" velocity="1.9634" lower="-2.0943951" upper="2.0943951" />
        <parent link="${name}_link_5"/>
        <child link="${name}_link_6"/>
    </joint>

    <joint name="${name}_joint_7" type="revolute">
        <origin xyz="0 0.057 0.0455" rpy="-1.570796326 0 0" />
        <axis xyz="0 0 1" />
        <limit effort="30" velocity="1.9634" lower="-2.9670" upper="2.9670" />
        <parent link="${name}_link_6"/>
        <child link="${name}_link_7"/>
    </joint>

    <joint name="${name}_link-7_to_cp" type="fixed">
        <origin xyz="0 0 0.02" rpy="0 0 0" />
        <parent link="${name}_link_7"/>
        <child link="${name}_link_tcp"/>
    </joint>

</xacro:macro>
</robot>