<?xml version="1.0" ?>
<!-- =================================================================================== -->
<!-- |    This document was autogenerated by xacro from kuka_lwr_arm_with_gripper.urdf.xacro | -->
<!-- |    EDITING THIS FILE BY HAND IS NOT RECOMMENDED                                 | -->
<!-- =================================================================================== -->
<robot name="kuka_lwr" xmlns:xacro="http://wiki.ros.org/xacro">
  <!-- ################################################################# -->
  <!-- Kuka_LWR arm -->
  <!-- ################################################################# -->
  <material name="IPA/Orange">
    <color rgba="1.0 0.5 0.0 1.0"/>
  </material>
  <material name="black">
    <color rgba="0.5 0.5 0.5 1"/>
  </material>
  <link name="kuka_link_footprint"/>
  <link name="kuka_link_base">
    <visual>
      <origin rpy="0 0 0" xyz="0 0 0"/>
      <geometry>
        <box size="0.01 0.01 0.01"/>
      </geometry>
      <material name="black">
      </material>
    </visual>
  </link>
  <link name="kuka_link_1">
    <visual>
      <origin rpy="0 0 0" xyz="0 0 0"/>
      <geometry>
        <mesh filename="package://klwr_description/mesh/joint_1.stl"/>
      </geometry>
      <material name="IPA/Orange">
      </material>
    </visual>
  </link>
  <link name="kuka_link_2">
    <visual>
      <origin rpy="0 0 0" xyz="0 0 0"/>
      <geometry>
        <mesh filename="package://klwr_description/mesh/joint_2.stl"/>
      </geometry>
      <material name="IPA/Orange">
      </material>
    </visual>
  </link>
  <link name="kuka_link_3">
    <visual>
      <origin rpy="0 0 0" xyz="0 0 0"/>
      <geometry>
        <mesh filename="package://klwr_description/mesh/joint_3.stl"/>
      </geometry>
      <material name="IPA/Orange">
      </material>
    </visual>
  </link>
  <link name="kuka_link_4">
    <visual>
      <origin rpy="0 0 0" xyz="0 0 0"/>
      <geometry>
        <mesh filename="package://klwr_description/mesh/joint_4.stl"/>
      </geometry>
      <material name="IPA/Orange">
      </material>
    </visual>
  </link>
  <link name="kuka_link_5">
    <visual>
      <origin rpy="0 0 0" xyz="0 0 0"/>
      <geometry>
        <mesh filename="package://klwr_description/mesh/joint_5.stl"/>
      </geometry>
      <material name="IPA/Orange">
      </material>
    </visual>
  </link>
  <link name="kuka_link_6">
    <visual>
      <origin rpy="0 0 0" xyz="0 0 0"/>
      <geometry>
        <mesh filename="package://klwr_description/mesh/joint_6.stl"/>
      </geometry>
      <material name="IPA/Orange">
      </material>
    </visual>
  </link>
  <link name="kuka_link_7">
    <visual>
      <origin rpy="0 0 0" xyz="0 0 0"/>
      <geometry>
        <mesh filename="package://klwr_description/mesh/joint_7.stl"/>
      </geometry>
      <material name="IPA/Orange">
      </material>
    </visual>
  </link>
  <link name="kuka_link_tcp"/>
  <joint name="kuka_joint_footprint" type="fixed">
    <origin rpy="0 0 0" xyz="0 0 0.1185"/>
    <parent link="kuka_link_footprint"/>
    <child link="kuka_link_base"/>
  </joint>
  <joint name="kuka_joint_1" type="revolute">
    <origin rpy="0 0 0" xyz="0 0 0"/>
    <axis xyz="0 0 1"/>
    <limit effort="200" lower="-2.9670" upper="2.9670" velocity="1.9634"/>
    <parent link="kuka_link_base"/>
    <child link="kuka_link_1"/>
  </joint>
  <joint name="kuka_joint_2" type="revolute">
    <origin rpy="1.570796326 0 0" xyz="0 -0.002 0.1915"/>
    <axis xyz="0 0 1"/>
    <limit effort="200" lower="-0.5235" upper="3.66509" velocity="1.9634"/>
    <parent link="kuka_link_1"/>
    <child link="kuka_link_2"/>
  </joint>
  <joint name="kuka_joint_3" type="revolute">
    <origin rpy="-1.570796326 0 0" xyz="0 0.2085 0"/>
    <axis xyz="0 0 1"/>
    <limit effort="100" lower="-2.9670" upper="2.9670" velocity="1.9634"/>
    <parent link="kuka_link_2"/>
    <child link="kuka_link_3"/>
  </joint>
  <joint name="kuka_joint_4" type="revolute">
    <origin rpy="-1.570796326 0 0" xyz="0 0.002 0.1915"/>
    <axis xyz="0 0 1"/>
    <limit effort="100" lower="-2.0943" upper="2.0943" velocity="1.9634"/>
    <parent link="kuka_link_3"/>
    <child link="kuka_link_4"/>
  </joint>
  <joint name="kuka_joint_5" type="revolute">
    <origin rpy="1.570796326 0 0" xyz="0 -0.2085 0"/>
    <axis xyz="0 0 1"/>
    <limit effort="100" lower="-2.9670" upper="2.9670" velocity="1.9634"/>
    <parent link="kuka_link_4"/>
    <child link="kuka_link_5"/>
  </joint>
  <joint name="kuka_joint_6" type="revolute">
    <origin rpy="1.570796326 0 0" xyz="0 0.046 0.1815"/>
    <axis xyz="0 0 1"/>
    <limit effort="30" lower="-2.0943951" upper="2.0943951" velocity="1.9634"/>
    <parent link="kuka_link_5"/>
    <child link="kuka_link_6"/>
  </joint>
  <joint name="kuka_joint_7" type="revolute">
    <origin rpy="-1.570796326 0 0" xyz="0 0.057 0.0455"/>
    <axis xyz="0 0 1"/>
    <limit effort="30" lower="-2.9670" upper="2.9670" velocity="1.9634"/>
    <parent link="kuka_link_6"/>
    <child link="kuka_link_7"/>
  </joint>
  <joint name="kuka_link-7_to_cp" type="fixed">
    <origin rpy="0 0 0" xyz="0 0 0.02"/>
    <parent link="kuka_link_7"/>
    <child link="kuka_link_tcp"/>
  </joint>
  <!-- ################################################################# -->
  <!-- ROS Industrial standard frames -->
  <!-- ################################################################# -->
  <!-- ROS-Industrial BASE frame, base_link to Fanuc World Coordinates transform -->
  <link name="kuka_base"/>
  <joint name="kuka_base_to_footprint" type="fixed">
    <origin rpy="0 0 0" xyz="0 0 0"/>
    <parent link="kuka_link_footprint"/>
    <child link="kuka_base"/>
  </joint>
  <!-- ROS-Industrial FLANGE frame, attachment point for EEF models -->
  <link name="kuka_flange"/>
  <joint name="kuka_tcp_to_flange" type="fixed">
    <origin rpy="0 0 0" xyz="0 0 0"/>
    <parent link="kuka_link_tcp"/>
    <child link="kuka_flange"/>
  </joint>
  <!-- ROS-Industrial TOOL-0 frame, all-zeros tool frame -->
  <link name="kuka_tool0"/>
  <joint name="kuka_flange_to_tool0" type="fixed">
    <origin rpy="0 0 0" xyz="0 0 0"/>
    <parent link="kuka_flange"/>
    <child link="kuka_tool0"/>
  </joint>
  <!-- ################################################################# -->
  <!-- A gripper -->
  <!-- ################################################################# -->
  <material name="grey">
    <color rgba="0.5 0.5 0.5 1"/>
  </material>
  <link name="kuka_gripper">
    <visual>
      <origin rpy="0 0 0" xyz="0 0 -0.05"/>
      <geometry>
        <box size="0.05 0.05 0.1"/>
      </geometry>
      <material name="grey"/>
    </visual>
  </link>
  <joint name="kuka_flange_to_gripper" type="fixed">
    <origin rpy="0 0 0" xyz="0 0 0.10"/>
    <parent link="kuka_flange"/>
    <child link="kuka_gripper"/>
  </joint>
</robot>
